Workbook

Sheet Applicants_Raw
A1: Student_ID | B1: Name | C1: Department | D1: Standardized_Department | E1: Test_1_Score | F1: Test_2_Score | G1: Test_3_Score | H1: Attendance_% | I1: Application_Date | J1: Internship_Pref | K1: Assignment_Completion_% | L1: Weighted_Score | M1: Eligibility_Status
A2: S001 | B2: Aadhya Jain | C2: CSE | D2: =VLOOKUP(C2, Dept_Lookup!$A$2:$B$17, 2, FALSE) -> Computer Science | E2: 75 | F2: 59 | G2: 65 | H2: 0.77 | I2: 45893 | J2: Company C | K2: 0.9 | L2: =E2*Scoring_Weights!$B$2 + F2*Scoring_Weights!$B$3 + G2*Scoring_Weights!$B$4 -> 64.4 | M2: =IF(AND(H2>=(VLOOKUP(J2,Interview_Slots!$A$2:$D$5,4,FALSE)/100), L2>=VLOOKUP(J2,Interview_Slots!$A$2:$D$5,3,FALSE)), "Eligible", "Not Eligible") -> Eligible
A3: S002 | B3: Myra Chatterjee | C3: Comp Sci | D3: =VLOOKUP(C3, Dept_Lookup!$A$2:$B$17, 2, FALSE) -> Computer Science | E3: 66 | F3: 75 | G3: 70 | H3: 0.86 | I3: 45816 | J3: Company B | K3: 0.82 | L3: =E3*Scoring_Weights!$B$2 + F3*Scoring_Weights!$B$3 + G3*Scoring_Weights!$B$4 -> 71.15 | M3: =IF(AND(H3>=(VLOOKUP(J3,Interview_Slots!$A$2:$D$5,4,FALSE)/100), L3>=VLOOKUP(J3,Interview_Slots!$A$2:$D$5,3,FALSE)), "Eligible", "Not Eligible") -> Eligible
A4: S003 | B4: Diya Gupta | C4: CS | D4: =VLOOKUP(C4, Dept_Lookup!$A$2:$B$17, 2, FALSE) -> Computer Science | E4: 98 | F4: 67 | G4: 82 | H4: 0.91 | I4: 45893 | J4: Company D | K4: 0.79 | L4: =E4*Scoring_Weights!$B$2 + F4*Scoring_Weights!$B$3 + G4*Scoring_Weights!$B$4 -> 79.15 | M4: =IF(AND(H4>=(VLOOKUP(J4,Interview_Slots!$A$2:$D$5,4,FALSE)/100), L4>=VLOOKUP(J4,Interview_Slots!$A$2:$D$5,3,FALSE)), "Eligible", "Not Eligible") -> Eligible
A5: S004 | B5: Sai Agarwal | C5: Computer Science | D5: =VLOOKUP(C5, Dept_Lookup!$A$2:$B$17, 2, FALSE) -> Computer Science | E5: 96 | F5: 69 | G5: 76 | H5: 0.99 | I5: 45865 | J5: Company B | K5: 0.84 | L5: =E5*Scoring_Weights!$B$2 + F5*Scoring_Weights!$B$3 + G5*Scoring_Weights!$B$4 -> 76.55 | M5: =IF(AND(H5>=(VLOOKUP(J5,Interview_Slots!$A$2:$D$5,4,FALSE)/100), L5>=VLOOKUP(J5,Interview_Slots!$A$2:$D$5,3,FALSE)), "Eligible", "Not Eligible") -> Eligible
A6: S005 | B6: Anika Mukherjee | C6: ECE | D6: =VLOOKUP(C6, Dept_Lookup!$A$2:$B$17, 2, FALSE) -> Electronics | E6: 78 | F6: 91 | G6: 96 | H6: 0.81 | I6: 45915 | J6: Company A | K6: 0.73 | L6: =E6*Scoring_Weights!$B$2 + F6*Scoring_Weights!$B$3 + G6*Scoring_Weights!$B$4 -> 91.55 | M6: =IF(AND(H6>=(VLOOKUP(J6,Interview_Slots!$A$2:$D$5,4,FALSE)/100), L6>=VLOOKUP(J6,Interview_Slots!$A$2:$D$5,3,FALSE)), "Eligible", "Not Eligible") -> Eligible
A7: S006 | B7: Krishna Agarwal | C7: Electro | D7: =VLOOKUP(C7, Dept_Lookup!$A$2:$B$17, 2, FALSE) -> Electronics | E7: 80 | F7: 63 | G7: 96 | H7: 0.72 | I7: 45860 | J7: Company D | K7: 0.86 | L7: =E7*Scoring_Weights!$B$2 + F7*Scoring_Weights!$B$3 + G7*Scoring_Weights!$B$4 -> 82.05 | M7: =IF(AND(H7>=(VLOOKUP(J7,Interview_Slots!$A$2:$D$5,4,FALSE)/100), L7>=VLOOKUP(J7,Interview_Slots!$A$2:$D$5,3,FALSE)), "Eligible", "Not Eligible") -> Not Eligible
A8: S007 | B8: Ananya Mishra | C8: ELEC | D8: =VLOOKUP(C8, Dept_Lookup!$A$2:$B$17, 2, FALSE) -> Electronics | E8: 80 | F8: 93 | G8: 85 | H8: 0.78 | I8: 45872 | J8: Company D | K8: 0.94 | L8: =E8*Scoring_Weights!$B$2 + F8*Scoring_Weights!$B$3 + G8*Scoring_Weights!$B$4 -> 87.05 | M8: =IF(AND(H8>=(VLOOKUP(J8,Interview_Slots!$A$2:$D$5,4,FALSE)/100), L8>=VLOOKUP(J8,Interview_Slots!$A$2:$D$5,3,FALSE)), "Eligible", "Not Eligible") -> Not Eligible
A9: S008 | B9: Reyansh Chopra | C9: Electronics | D9: =VLOOKUP(C9, Dept_Lookup!$A$2:$B$17, 2, FALSE) -> Electronics | E9: 91 | F9: 75 | G9: 89 | H9: 0.88 | I9: 45880 | J9: Company C | K9: 0.84 | L9: =E9*Scoring_Weights!$B$2 + F9*Scoring_Weights!$B$3 + G9*Scoring_Weights!$B$4 -> 84.4 | M9: =IF(AND(H9>=(VLOOKUP(J9,Interview_Slots!$A$2:$D$5,4,FALSE)/100), L9>=VLOOKUP(J9,Interview_Slots!$A$2:$D$5,3,FALSE)), "Eligible", "Not Eligible") -> Eligible
A10: S009 | B10: Vihaan Singh | C10: Mech | D10: =VLOOKUP(C10, Dept_Lookup!$A$2:$B$17, 2, FALSE) -> Mechanical | E10: 77 | F10: 90 | G10: 82 | H10: 0.79 | I10: 45874 | J10: Company A | K10: 0.84 | L10: =E10*Scoring_Weights!$B$2 + F10*Scoring_Weights!$B$3 + G10*Scoring_Weights!$B$4 -> 84.05 | M10: =IF(AND(H10>=(VLOOKUP(J10,Interview_Slots!$A$2:$D$5,4,FALSE)/100), L10>=VLOOKUP(J10,Interview_Slots!$A$2:$D$5,3,FALSE)), "Eligible", "Not Eligible") -> Eligible
A11: S010 | B11: Ananya Mukherjee | C11: ME | D11: =VLOOKUP(C11, Dept_Lookup!$A$2:$B$17, 2, FALSE) -> Mechanical | E11: 66 | F11: 73 | G11: 88 | H11: 0.68 | I11: 45877 | J11: Company C | K11: 0.65 | L11: =E11*Scoring_Weights!$B$2 + F11*Scoring_Weights!$B$3 + G11*Scoring_Weights!$B$4 -> 79.45 | M11: =IF(AND(H11>=(VLOOKUP(J11,Interview_Slots!$A$2:$D$5,4,FALSE)/100), L11>=VLOOKUP(J11,Interview_Slots!$A$2:$D$5,3,FALSE)), "Eligible", "Not Eligible") -> Not Eligible
A12: S011 | B12: Ananya Singh | C12: Mechanical Engg | D12: =VLOOKUP(C12, Dept_Lookup!$A$2:$B$17, 2, FALSE) -> Mechanical | E12: 93 | F12: 78 | G12: 62 | H12: 0.85 | I12: 45913 | J12: Company B | K12: 0.96 | L12: =E12*Scoring_Weights!$B$2 + F12*Scoring_Weights!$B$3 + G12*Scoring_Weights!$B$4 -> 72.25 | M12: =IF(AND(H12>=(VLOOKUP(J12,Interview_Slots!$A$2:$D$5,4,FALSE)/100), L12>=VLOOKUP(J12,Interview_Slots!$A$2:$D$5,3,FALSE)), "Eligible", "Not Eligible") -> Eligible
A13: S012 | B13: Ananya Rao | C13: Mechanical | D13: =VLOOKUP(C13, Dept_Lookup!$A$2:$B$17, 2, FALSE) -> Mechanical | E13: 97 | F13: 62 | G13: 91 | H13: 0.94 | I13: 45847 | J13: Company C | K13: 0.77 | L13: =E13*Scoring_Weights!$B$2 + F13*Scoring_Weights!$B$3 + G13*Scoring_Weights!$B$4 -> 81.75 | M13: =IF(AND(H13>=(VLOOKUP(J13,Interview_Slots!$A$2:$D$5,4,FALSE)/100), L13>=VLOOKUP(J13,Interview_Slots!$A$2:$D$5,3,FALSE)), "Eligible", "Not Eligible") -> Eligible
... A464: S463 | B464: Aparajita Das | C464: CIV | D464: =VLOOKUP(C464, Dept_Lookup!$A$2:$B$17, 2, FALSE) -> Civil | E464: 77 | F464: 93 | G464: 76 | H464: 0.79 | I464: 45865 | J464: Company C | K464: 0.73 | L464: =E464*Scoring_Weights!$B$2 + F464*Scoring_Weights!$B$3 + G464*Scoring_Weights!$B$4 -> 82.1 | M464: =IF(AND(H464>=(VLOOKUP(J464,Interview_Slots!$A$2:$D$5,4,FALSE)/100), L464>=VLOOKUP(J464,Interview_Slots!$A$2:$D$5,3,FALSE)), "Eligible", "Not Eligible") -> Eligible

Sheet Allocation
A1: Student_ID | B1: Name | C1: Standardized_Department | D1: Internship_Pref | E1: Weighted_Score | F1: Eligibility_Status | G1: Rank | H1: Allocation_Status
A2: S001 | B2: Aadhya Jain | C2: Computer Science | D2: Company C | E2: 64.4 | F2: Eligible | G2: =IFERROR(__xludf.DUMMYFUNCTION("RANK(E2, FILTER($E$2:$E1000, $D$2:$D1000=D2), 0)"),108.0) -> 108 | H2: =IF(G2<=VLOOKUP(D2, Interview_Slots!$A$2:$B$5, 2, FALSE), "Allocated", "Not Allocated") -> Not Allocated
A3: S002 | B3: Myra Chatterjee | C3: Computer Science | D3: Company B | E3: 71.15 | F3: Eligible | G3: =IFERROR(__xludf.DUMMYFUNCTION("RANK(E3, FILTER($E$2:$E1000, $D$2:$D1000=D3), 0)"),98.0) -> 98 | H3: =IF(G3<=VLOOKUP(D3, Interview_Slots!$A$2:$B$5, 2, FALSE), "Allocated", "Not Allocated") -> Not Allocated
A4: S003 | B4: Diya Gupta | C4: Computer Science | D4: Company D | E4: 79.15 | F4: Eligible | G4: =IFERROR(__xludf.DUMMYFUNCTION("RANK(E4, FILTER($E$2:$E1000, $D$2:$D1000=D4), 0)"),50.0) -> 50 | H4: =IF(G4<=VLOOKUP(D4, Interview_Slots!$A$2:$B$5, 2, FALSE), "Allocated", "Not Allocated") -> Not Allocated
A5: S004 | B5: Sai Agarwal | C5: Computer Science | D5: Company B | E5: 76.55 | F5: Eligible | G5: =IFERROR(__xludf.DUMMYFUNCTION("RANK(E5, FILTER($E$2:$E1000, $D$2:$D1000=D5), 0)"),66.0) -> 66 | H5: =IF(G5<=VLOOKUP(D5, Interview_Slots!$A$2:$B$5, 2, FALSE), "Allocated", "Not Allocated") -> Not Allocated
A6: S005 | B6: Anika Mukherjee | C6: Electronics | D6: Company A | E6: 91.55 | F6: Eligible | G6: =IFERROR(__xludf.DUMMYFUNCTION("RANK(E6, FILTER($E$2:$E1000, $D$2:$D1000=D6), 0)"),2.0) -> 2 | H6: =IF(G6<=VLOOKUP(D6, Interview_Slots!$A$2:$B$5, 2, FALSE), "Allocated", "Not Allocated") -> Allocated
A7: S006 | B7: Krishna Agarwal | C7: Electronics | D7: Company D | E7: 82.05 | F7: Not Eligible | G7: =IFERROR(__xludf.DUMMYFUNCTION("RANK(E7, FILTER($E$2:$E1000, $D$2:$D1000=D7), 0)"),37.0) -> 37 | H7: =IF(G7<=VLOOKUP(D7, Interview_Slots!$A$2:$B$5, 2, FALSE), "Allocated", "Not Allocated") -> Not Allocated
A8: S007 | B8: Ananya Mishra | C8: Electronics | D8: Company D | E8: 87.05 | F8: Not Eligible | G8: =IFERROR(__xludf.DUMMYFUNCTION("RANK(E8, FILTER($E$2:$E1000, $D$2:$D1000=D8), 0)"),17.0) -> 17 | H8: =IF(G8<=VLOOKUP(D8, Interview_Slots!$A$2:$B$5, 2, FALSE), "Allocated", "Not Allocated") -> Allocated
A9: S008 | B9: Reyansh Chopra | C9: Electronics | D9: Company C | E9: 84.4 | F9: Eligible | G9: =IFERROR(__xludf.DUMMYFUNCTION("RANK(E9, FILTER($E$2:$E1000, $D$2:$D1000=D9), 0)"),29.0) -> 29 | H9: =IF(G9<=VLOOKUP(D9, Interview_Slots!$A$2:$B$5, 2, FALSE), "Allocated", "Not Allocated") -> Allocated
A10: S009 | B10: Vihaan Singh | C10: Mechanical | D10: Company A | E10: 84.05 | F10: Eligible | G10: =IFERROR(__xludf.DUMMYFUNCTION("RANK(E10, FILTER($E$2:$E1000, $D$2:$D1000=D10), 0)"),29.0) -> 29 | H10: =IF(G10<=VLOOKUP(D10, Interview_Slots!$A$2:$B$5, 2, FALSE), "Allocated", "Not Allocated") -> Allocated
A11: S010 | B11: Ananya Mukherjee | C11: Mechanical | D11: Company C | E11: 79.45 | F11: Not Eligible | G11: =IFERROR(__xludf.DUMMYFUNCTION("RANK(E11, FILTER($E$2:$E1000, $D$2:$D1000=D11), 0)"),53.0) -> 53 | H11: =IF(G11<=VLOOKUP(D11, Interview_Slots!$A$2:$B$5, 2, FALSE), "Allocated", "Not Allocated") -> Allocated
A12: S011 | B12: Ananya Singh | C12: Mechanical | D12: Company B | E12: 72.25 | F12: Eligible | G12: =IFERROR(__xludf.DUMMYFUNCTION("RANK(E12, FILTER($E$2:$E1000, $D$2:$D1000=D12), 0)"),92.0) -> 92 | H12: =IF(G12<=VLOOKUP(D12, Interview_Slots!$A$2:$B$5, 2, FALSE), "Allocated", "Not Allocated") -> Not Allocated
A13: S012 | B13: Ananya Rao | C13: Mechanical | D13: Company C | E13: 81.75 | F13: Eligible | G13: =IFERROR(__xludf.DUMMYFUNCTION("RANK(E13, FILTER($E$2:$E1000, $D$2:$D1000=D13), 0)"),41.0) -> 41 | H13: =IF(G13<=VLOOKUP(D13, Interview_Slots!$A$2:$B$5, 2, FALSE), "Allocated", "Not Allocated") -> Allocated
A14: S013 | B14: Aarohi Jain | C14: Civil | D14: Company A | E14: 77.4 | F14: Not Eligible | G14: =IFERROR(__xludf.DUMMYFUNCTION("RANK(E14, FILTER($E$2:$E1000, $D$2:$D1000=D14), 0)"),54.0) -> 54 | H14: =IF(G14<=VLOOKUP(D14, Interview_Slots!$A$2:$B$5, 2, FALSE), "Allocated", "Not Allocated") -> Allocated
A15: S014 | B15: Navya Menon | C15: Civil | D15: Company C | E15: 78.85 | F15: Eligible | G15: =IFERROR(__xludf.DUMMYFUNCTION("RANK(E15, FILTER($E$2:$E1000, $D$2:$D1000=D15), 0)"),57.0) -> 57 | H15: =IF(G15<=VLOOKUP(D15, Interview_Slots!$A$2:$B$5, 2, FALSE), "Allocated", "Not Allocated") -> Allocated
A16: S015 | B16: Aarav Sharma | C16: Civil | D16: Company B | E16: 82.95 | F16: Not Eligible | G16: =IFERROR(__xludf.DUMMYFUNCTION("RANK(E16, FILTER($E$2:$E1000, $D$2:$D1000=D16), 0)"),24.0) -> 24 | H16: =IF(G16<=VLOOKUP(D16, Interview_Slots!$A$2:$B$5, 2, FALSE), "Allocated", "Not Allocated") -> Allocated
A17: S016 | B17: Rohan Mehta | C17: Civil | D17: Company B | E17: 80.35 | F17: Eligible | G17: =IFERROR(__xludf.DUMMYFUNCTION("RANK(E17, FILTER($E$2:$E1000, $D$2:$D1000=D17), 0)"),44.0) -> 44 | H17: =IF(G17<=VLOOKUP(D17, Interview_Slots!$A$2:$B$5, 2, FALSE), "Allocated", "Not Allocated") -> Allocated
A18: S017 | B18: Kabir Iyer | C18: Computer Science | D18: Company B | E18: 73.65 | F18: Not Eligible | G18: =IFERROR(__xludf.DUMMYFUNCTION("RANK(E18, FILTER($E$2:$E1000, $D$2:$D1000=D18), 0)"),85.0) -> 85 | H18: =IF(G18<=VLOOKUP(D18, Interview_Slots!$A$2:$B$5, 2, FALSE), "Allocated", "Not Allocated") -> Not Allocated
A19: S018 | B19: Vihaan Reddy | C19: Computer Science | D19: Company D | E19: 82.3 | F19: Not Eligible | G19: =IFERROR(__xludf.DUMMYFUNCTION("RANK(E19, FILTER($E$2:$E1000, $D$2:$D1000=D19), 0)"),36.0) -> 36 | H19: =IF(G19<=VLOOKUP(D19, Interview_Slots!$A$2:$B$5, 2, FALSE), "Allocated", "Not Allocated") -> Not Allocated
A20: S019 | B20: Sameer Deshmukh | C20: Computer Science | D20: Company D | E20: 69.8 | F20: Not Eligible | G20: =IFERROR(__xludf.DUMMYFUNCTION("RANK(E20, FILTER($E$2:$E1000, $D$2:$D1000=D20), 0)"),98.0) -> 98 | H20: =IF(G20<=VLOOKUP(D20, Interview_Slots!$A$2:$B$5, 2, FALSE), "Allocated", "Not Allocated") -> Not Allocated
A21: S020 | B21: Rajesh Nair | C21: Computer Science | D21: Company D | E21: 73.25 | F21: Not Eligible | G21: =IFERROR(__xludf.DUMMYFUNCTION("RANK(E21, FILTER($E$2:$E1000, $D$2:$D1000=D21), 0)"),81.0) -> 81 | H21: =IF(G21<=VLOOKUP(D21, Interview_Slots!$A$2:$B$5, 2, FALSE), "Allocated", "Not Allocated") -> Not Allocated
A22: S021 | B22: Anil Verma | C22: Electronics | D22: Company C | E22: 81.8 | F22: Eligible | G22: =IFERROR(__xludf.DUMMYFUNCTION("RANK(E22, FILTER($E$2:$E1000, $D$2:$D1000=D22), 0)"),39.0) -> 39 | H22: =IF(G22<=VLOOKUP(D22, Interview_Slots!$A$2:$B$5, 2, FALSE), "Allocated", "Not Allocated") -> Allocated
A23: S022 | B23: Devendra Patel | C23: Electronics | D23: Company A | E23: 86.7 | F23: Eligible | G23: =IFERROR(__xludf.DUMMYFUNCTION("RANK(E23, FILTER($E$2:$E1000, $D$2:$D1000=D23), 0)"),16.0) -> 16 | H23: =IF(G23<=VLOOKUP(D23, Interview_Slots!$A$2:$B$5, 2, FALSE), "Allocated", "Not Allocated") -> Allocated
A24: S023 | B24: Manish Gupta | C24: Electronics | D24: Company C | E24: 77.45 | F24: Eligible | G24: =IFERROR(__xludf.DUMMYFUNCTION("RANK(E24, FILTER($E$2:$E1000, $D$2:$D1000=D24), 0)"),62.0) -> 62 | H24: =IF(G24<=VLOOKUP(D24, Interview_Slots!$A$2:$B$5, 2, FALSE), "Allocated", "Not Allocated") -> Allocated
A25: S024 | B25: Harsh Malhotra | C25: Electronics | D25: Company B | E25: 82.25 | F25: Eligible | G25: =IFERROR(__xludf.DUMMYFUNCTION("RANK(E25, FILTER($E$2:$E1000, $D$2:$D1000=D25), 0)"),28.0) -> 28 | H25: =IF(G25<=VLOOKUP(D25, Interview_Slots!$A$2:$B$5, 2, FALSE), "Allocated", "Not Allocated") -> Allocated
A26: S025 | B26: Pranav Kulkarni | C26: Mechanical | D26: Company A | E26: 83.5 | F26: Eligible | G26: =IFERROR(__xludf.DUMMYFUNCTION("RANK(E26, FILTER($E$2:$E1000, $D$2:$D1000=D26), 0)"),32.0) -> 32 | H26: =IF(G26<=VLOOKUP(D26, Interview_Slots!$A$2:$B$5, 2, FALSE), "Allocated", "Not Allocated") -> Allocated
A27: S026 | B27: Karan Singh | C27: Mechanical | D27: Company A | E27: 78.9 | F27: Eligible | G27: =IFERROR(__xludf.DUMMYFUNCTION("RANK(E27, FILTER($E$2:$E1000, $D$2:$D1000=D27), 0)"),46.0) -> 46 | H27: =IF(G27<=VLOOKUP(D27, Interview_Slots!$A$2:$B$5, 2, FALSE), "Allocated", "Not Allocated") -> Allocated
A28: S027 | B28: Suresh Bhatia | C28: Mechanical | D28: Company C | E28: 64.55 | F28: Eligible | G28: =IFERROR(__xludf.DUMMYFUNCTION("RANK(E28, FILTER($E$2:$E1000, $D$2:$D1000=D28), 0)"),107.0) -> 107 | H28: =IF(G28<=VLOOKUP(D28, Interview_Slots!$A$2:$B$5, 2, FALSE), "Allocated", "Not Allocated") -> Not Allocated
A29: S028 | B29: Aditya Choudhury | C29: Mechanical | D29: Company B | E29: 86.65 | F29: Eligible | G29: =IFERROR(__xludf.DUMMYFUNCTION("RANK(E29, FILTER($E$2:$E1000, $D$2:$D1000=D29), 0)"),15.0) -> 15 | H29: =IF(G29<=VLOOKUP(D29, Interview_Slots!$A$2:$B$5, 2, FALSE), "Allocated", "Not Allocated") -> Allocated
A30: S029 | B30: Sanjay Kapoor | C30: Civil | D30: Company B | E30: 86.15 | F30: Not Eligible | G30: =IFERROR(__xludf.DUMMYFUNCTION("RANK(E30, FILTER($E$2:$E1000, $D$2:$D1000=D30), 0)"),17.0) -> 17 | H30: =IF(G30<=VLOOKUP(D30, Interview_Slots!$A$2:$B$5, 2, FALSE), "Allocated", "Not Allocated") -> Allocated
A31: S030 | B31: Naveen Menon | C31: Civil | D31: Company B | E31: 89.4 | F31: Eligible | G31: =IFERROR(__xludf.DUMMYFUNCTION("RANK(E31, FILTER($E$2:$E1000, $D$2:$D1000=D31), 0)"),9.0) -> 9 | H31: =IF(G31<=VLOOKUP(D31, Interview_Slots!$A$2:$B$5, 2, FALSE), "Allocated", "Not Allocated") -> Allocated
A32: S031 | B32: Gopal Das | C32: Civil | D32: Company D | E32: 84 | F32: Eligible | G32: =IFERROR(__xludf.DUMMYFUNCTION("RANK(E32, FILTER($E$2:$E1000, $D$2:$D1000=D32), 0)"),28.0) -> 28 | H32: =IF(G32<=VLOOKUP(D32, Interview_Slots!$A$2:$B$5, 2, FALSE), "Allocated", "Not Allocated") -> Allocated
A33: S032 | B33: Abhishek Joshi | C33: Computer Science | D33: Company D | E33: 87.8 | F33: Eligible | G33: =IFERROR(__xludf.DUMMYFUNCTION("RANK(E33, FILTER($E$2:$E1000, $D$2:$D1000=D33), 0)"),12.0) -> 12 | H33: =IF(G33<=VLOOKUP(D33, Interview_Slots!$A$2:$B$5, 2, FALSE), "Allocated", "Not Allocated") -> Allocated
A34: S033 | B34: Siddharth Rao | C34: Computer Science | D34: Company D | E34: 77.75 | F34: Eligible | G34: =IFERROR(__xludf.DUMMYFUNCTION("RANK(E34, FILTER($E$2:$E1000, $D$2:$D1000=D34), 0)"),58.0) -> 58 | H34: =IF(G34<=VLOOKUP(D34, Interview_Slots!$A$2:$B$5, 2, FALSE), "Allocated", "Not Allocated") -> Not Allocated
A35: S034 | B35: Vikram Shetty | C35: Computer Science | D35: Company C | E35: 81.25 | F35: Eligible | G35: =IFERROR(__xludf.DUMMYFUNCTION("RANK(E35, FILTER($E$2:$E1000, $D$2:$D1000=D35), 0)"),44.0) -> 44 | H35: =IF(G35<=VLOOKUP(D35, Interview_Slots!$A$2:$B$5, 2, FALSE), "Allocated", "Not Allocated") -> Allocated
A36: S035 | B36: Aisha Khan | C36: Computer Science | D36: Company A | E36: 87.2 | F36: Eligible | G36: =IFERROR(__xludf.DUMMYFUNCTION("RANK(E36, FILTER($E$2:$E1000, $D$2:$D1000=D36), 0)"),14.0) -> 14 | H36: =IF(G36<=VLOOKUP(D36, Interview_Slots!$A$2:$B$5, 2, FALSE), "Allocated", "Not Allocated") -> Allocated
A37: S036 | B37: Priya Sharma | C37: Electronics | D37: Company C | E37: 81.2 | F37: Eligible | G37: =IFERROR(__xludf.DUMMYFUNCTION("RANK(E37, FILTER($E$2:$E1000, $D$2:$D1000=D37), 0)"),45.0) -> 45 | H37: =IF(G37<=VLOOKUP(D37, Interview_Slots!$A$2:$B$5, 2, FALSE), "Allocated", "Not Allocated") -> Allocated
A38: S037 | B38: Ananya Reddy | C38: Electronics | D38: Company B | E38: 72.6 | F38: Eligible | G38: =IFERROR(__xludf.DUMMYFUNCTION("RANK(E38, FILTER($E$2:$E1000, $D$2:$D1000=D38), 0)"),90.0) -> 90 | H38: =IF(G38<=VLOOKUP(D38, Interview_Slots!$A$2:$B$5, 2, FALSE), "Allocated", "Not Allocated") -> Not Allocated
A39: S038 | B39: Lakshmi Nair | C39: Electronics | D39: Company A | E39: 67.95 | F39: Eligible | G39: =IFERROR(__xludf.DUMMYFUNCTION("RANK(E39, FILTER($E$2:$E1000, $D$2:$D1000=D39), 0)"),96.0) -> 96 | H39: =IF(G39<=VLOOKUP(D39, Interview_Slots!$A$2:$B$5, 2, FALSE), "Allocated", "Not Allocated") -> Not Allocated
A40: S039 | B40: Kavya Iyer | C40: Electronics | D40: Company A | E40: 83.05 | F40: Eligible | G40: =IFERROR(__xludf.DUMMYFUNCTION("RANK(E40, FILTER($E$2:$E1000, $D$2:$D1000=D40), 0)"),35.0) -> 35 | H40: =IF(G40<=VLOOKUP(D40, Interview_Slots!$A$2:$B$5, 2, FALSE), "Allocated", "Not Allocated") -> Allocated
...

Sheet Pivot Table 1

Sheet Dashboard

Sheet Dept_Lookup
A1: Variant | B1: Standard_Department
A2: CSE | B2: Computer Science
A3: Comp Sci | B3: Computer Science
A4: CS | B4: Computer Science
A5: Computer Science | B5: Computer Science
A6: ECE | B6: Electronics
A7: Electro | B7: Electronics
A8: ELEC | B8: Electronics
A9: Electronics | B9: Electronics
A10: Mech | B10: Mechanical
A11: ME | B11: Mechanical
A12: Mechanical Engg | B12: Mechanical
... A17: Civil | B17: Civil

Sheet Interview_Slots
A1: Company | B1: Interview_Slots_Available | C1: Min_WeightedScore | D1: Min_Attendance_%
A2: Company A | B2: 60 | C2: 65 | D2: 75
A3: Company B | B3: 45 | C3: 70 | D3: 80
A4: Company C | B4: 80 | C4: 60 | D4: 70
A5: Company D | B5: 30 | C5: 75 | D5: 85

Sheet Scoring_Weights
A1: Test | B1: Weight
A2: Test_1 | B2: 0.15
A3: Test_2 | B3: 0.35
A4: Test_3 | B4: 0.5
